<?xml version="1.0"?>
<robot name="jetson-car">

  <material name="blue"><color rgba="0 0 0.8 1"/></material>
  <material name="black"><color rgba="0 0 0 1"/></material>

  <link name="base_link">
    <visual>
      <geometry><sphere radius="0.01"/></geometry>
      <material name="black"/>
    </visual>
  </link>

  <link name="chassis">
    <visual>
      <origin xyz="0.074 0 0.034" rpy="0 0 0"/>
      <geometry><box size="0.20 0.10 0.05"/></geometry>
      <material name="blue"/>
    </visual>
  </link>
  <joint name="base_to_chassis" type="fixed">
    <parent link="base_link"/>
    <child link="chassis"/>
  </joint>

  <link name="rear_left_wheel">
    <visual>
      <origin xyz="0 0 0" rpy="1.5708 0 0"/>
      <geometry><cylinder radius="0.034" length="0.02"/></geometry>
      <material name="black"/>
    </visual>
  </link>
  <joint name="rl_wheel_joint" type="continuous">
    <parent link="base_link"/>
    <child link="rear_left_wheel"/>
    <origin xyz="0 0.0665 0.034" rpy="0 0 0"/>
    <axis xyz="0 1 0"/>
  </joint>

  <link name="rear_right_wheel">
    <visual>
      <origin xyz="0 0 0" rpy="1.5708 0 0"/>
      <geometry><cylinder radius="0.034" length="0.02"/></geometry>
      <material name="black"/>
    </visual>
  </link>
  <joint name="rr_wheel_joint" type="continuous">
    <parent link="base_link"/>
    <child link="rear_right_wheel"/>
    <origin xyz="0 -0.0665 0.034" rpy="0 0 0"/>
    <axis xyz="0 1 0"/>
  </joint>

  <link name="front_left_wheel">
    <visual>
      <origin xyz="0 0 0" rpy="1.5708 0 0"/>
      <geometry><cylinder radius="0.034" length="0.02"/></geometry>
      <material name="black"/>
    </visual>
  </link>
  <joint name="fl_wheel_joint" type="continuous">
    <parent link="base_link"/>
    <child link="front_left_wheel"/>
    <origin xyz="0.148 0.0665 0.034" rpy="0 0 0"/>
    <axis xyz="0 1 0"/>
  </joint>

  <link name="front_right_wheel">
    <visual>
      <origin xyz="0 0 0" rpy="1.5708 0 0"/>
      <geometry><cylinder radius="0.034" length="0.02"/></geometry>
      <material name="black"/>
    </visual>
  </link>
  <joint name="fr_wheel_joint" type="continuous">
    <parent link="base_link"/>
    <child link="front_right_wheel"/>
    <origin xyz="0.148 -0.0665 0.034" rpy="0 0 0"/>
    <axis xyz="0 1 0"/>
  </joint>

</robot>